Workbook

Sheet Тит.лист
A1: СТАТИСТИКАЛЫК ОТЧЕТТУУЛУК | L1: СТАТИСТИЧЕСКАЯ ОТЧЕТНОСТЬ
A2: Кыргыз Республикасынын «Расмий статистика жөнүндө» мыйзамына ылайык Жашыруундулугуна кепилдик берилет | L2: в соответствии с Законом Кыргызской Республики «Об официальной статистике» Конфиденциальность гарантируется
A3: Маалыматтарды берүү тартибин, мөөнөтүн бузуу, аны бурмалап берүү, жашыруундуулугун сактабагандыгы Кыргыз Республикасынын мыйзамдарында бекитилген жоопкерчиликти тартууга алып келет | L3: Нарушение порядка, сроков представления информации, ее искажение и несоблюдение конфиденциальности влечет ответственность, установленную законодательством Кыргызской Республики
A5: № 1-Е — ФОРМАСЫ | L5: ФОРМА №-1-Е | S5: 6126073
S6: ГКУД
A7: ЖЫЛДЫК, ЖАРЫМ ЖЫЛДЫК | L7: ГОДОВАЯ, ПОЛУГОДОВАЯ
A9: Кыргыз Республикасынын Улутстаткомунун 31.05.2022-ж. № 3 токтому менен бекитилген | L9: Утверждена постановлением Нацстаткома Кыргызской Республики от 31.05.2023 г. № 3
A11: ТЕРГӨӨ ИШТЕРИ БОЮНЧА ОТЧЕТ | L11: ОТЧЕТ О СЛЕДСТВЕННОЙ РАБОТЕ
A12: за ноябрь 2025 г. (ж.) үчүн
A14: Кыргыз Республикасынын ИИМ, ЖАМК, УКМК, МБК прокуратура органдары Башкы прокуратурага бекитилген графиктерге ылайык; Башкы прокуратура 25 январда жана 25 июлда Кыргыз Республикасынын Улутстаткомуна ТАПШЫРАТ | L14: ПРЕДСТАВЛЯЮТ Органы прокуратуры, МВД, ГСИН, ГКНБ, ГТС предоставляют отчет Генеральной прокуратуре по установленному графику; Генеральная прокуратура – годовую 25 января, полугодовую 25 июля Нацстаткому Кыргызской Республики
O17: ОКПО
A18: Ишкана, уюмдун аталышы Наименование предприятия, организации
G20: СОАТЕ (статистикалык орган тарабынан толтурулат) (заполняется статистическим органом)
A21: Аймагы (облусу, району, шаары, калктуу пункту) Территория (область, район, город, нас. пункт)
A22: Дареги (почта индекси, көчөсү, үй №) Телефон E-mail (электрондук почта электронная почта) Адрес (почтовый индекс, улица, № дома)
A23: Экономикалык ишмердиктин иш жүзүндөгү түрү (негизги) Фактический вид экономической деятельности (основной)
P24: ГКЭД
A26: «__09__»__декабрь___ 20____-ж. (г.) | H26: Мийзамов Ө.К.
H27: аткаруучунун аты-жөнү, телефон № (фамилия и № телефона исполнителя)
A29: Жетекчи | D29: Сыдыгалиев Б.О.
A30: Руководитель | D30: фамилиясы, аты, атасынын аты (ФИО) | Q30: колу (подпись)
A33: Статистикалык отчеттуулукту кабыл алуучу статистикалык органдын координаттары; Координаты статистического органа, принимающего статистическую отчетность:
A35: Телефон: 32-4652, 66-4042, факс: 66-0138, 62-5671, e-mail: nsc_mail@stat.kg, Веб-сайт Нацстаткома-www.stat.kg

Sheet Отчет 1-Е Р.1
D1: Прокуратура | H1: МВД | L1: ГКНБ | P1: ГСИН
A2: Г. | B2: Раздел 1. Оконч. дела по видам преступл. (без повторно оконченных) | C2: № | D2: ЗАРЕГ. (дел) | E2: В СУД (дел) | F2: ОБВИН. (лиц) | G2: ПРЕКРАЩ. (дел) | H2: ЗАРЕГ. (дел) 2 | I2: В СУД (дел) 2 | J2: ОБВИН. (лиц) 2 | K2: ПРЕКРАЩ. (дел) 2 | L2: ЗАРЕГ. (дел) 3 | M2: В СУД (дел) 3 | N2: ОБВИН. (лиц) 3 | O2: ПРЕКРАЩ. (дел) 3 | P2: ЗАРЕГ. (дел) 4 | Q2: В СУД (дел) 4 | R2: ОБВИН. (лиц) 4 | S2: ПРЕКРАЩ. (дел) 4 | T2: в т.ч. соверш. женщ. (лиц) | U2: в т.ч. соверш. реб. (лиц) | V2: в т.ч. соверш. в отн. женщ. (лиц) | W2: в т.ч. соверш. в отнош. реб. (лиц)
C3: 0 | D3: 1 | E3: 2 | F3: 3 | G3: 4 | H3: 5 | I3: 6 | J3: 7 | K3: 8 | L3: 9 | M3: 10 | N3: 11 | O3: 12 | P3: 13 | Q3: 14 | R3: 15 | S3: 16 | T3: 17 | U3: 18 | V3: 19 | W3: 20
A4: Раздел VI | C4: 1 | D4: =D5+D14+D25+D32+D42+D46+D56+D64+D82 -> 0 | E4: =E5+E14+E25+E32+E42+E46+E56+E64+E82 -> 0 | F4: =F5+F14+F25+F32+F42+F46+F56+F64+F82 -> 0 | G4: =G5+G14+G25+G32+G42+G46+G56+G64+G82 -> 0 | H4: =H5+H14+H25+H32+H42+H46+H56+H64+H82 -> 250 | I4: =I5+I14+I25+I32+I42+I46+I56+I64+I82 -> 152 | J4: =J5+J14+J25+J32+J42+J46+J56+J64+J82 -> 183 | K4: =K5+K14+K25+K32+K42+K46+K56+K64+K82 -> 53 | ... W4: =W5+W14+W25+W32+W42+W46+W56+W64+W82 -> 22
A5: Глава 19 | C5: 2 | D5: =SUM(D6:D13) -> 0 | E5: =SUM(E6:E13) -> 0 | F5: =SUM(F6:F13) -> 0 | G5: =SUM(G6:G13) -> 0 | H5: =SUM(H6:H13) -> 10 | I5: =SUM(I6:I13) -> 8 | J5: =SUM(J6:J13) -> 10 | K5: =SUM(K6:K13) -> 0 | ... W5: =SUM(W6:W13) -> 0
A6: Глава 19 | B6: ст.122 | C6: 3 | H6: 8 | I6: 8 | J6: 10 | V6: 1
A7: Глава 19 | B7: ст.123 | C7: 4
A8: Глава 19 | B8: ст.124 | C8: 5
A9: Глава 19 | B9: ст.125 | C9: 6
A10: Глава 19 | B10: ст.126 | C10: 7
A11: Глава 19 | B11: ст.127 | C11: 8
A12: Глава 19 | B12: ст.128 | C12: 9 | H12: 2
A13: Глава 19 | B13: ст.129 | C13: 10
A14: Глава 20 | C14: 11 | D14: =SUM(D15:D24) -> 0 | E14: =SUM(E15:E24) -> 0 | F14: =SUM(F15:F24) -> 0 | G14: =SUM(G15:G24) -> 0 | H14: =SUM(H15:H24) -> 108 | I14: =SUM(I15:I24) -> 54 | J14: =SUM(J15:J24) -> 71 | K14: =SUM(K15:K24) -> 42 | ... W14: =SUM(W15:W24) -> 6
A15: Глава 20 | B15: ст.130 | C15: 12 | H15: 14 | I15: 13 | J15: 13 | T15: 4 | U15: 1 | V15: 4 | W15: 1
A16: Глава 20 | B16: ст.131 | C16: 13 | H16: 47 | I16: 22 | J16: 34 | K16: 20 | T16: 4 | U16: 2 | V16: 7 | W16: 1
A17: Глава 20 | B17: ст.132 | C17: 14 | T17: 2
A18: Глава 20 | B18: ст.133 | C18: 15
A19: Глава 20 | B19: ст.134 | C19: 16 | H19: 1 | I19: 1 | K19: 1 | T19: 1 | W19: 1
A20: Глава 20 | B20: ст.135 | C20: 17
A21: Глава 20 | B21: ст.136 | C21: 18 | H21: 42 | I21: 16 | J21: 19 | K21: 20 | T21: 6 | V21: 19 | W21: 3
A22: Глава 20 | B22: ст.137 | C22: 19
A23: Глава 20 | B23: ст.138 | C23: 20 | H23: 4 | I23: 2 | J23: 5 | K23: 1 | V23: 3
A24: Глава 20 | B24: ст.139 | C24: 21
A25: Глава 21 | C25: 22 | D25: =SUM(D26:D31) -> 0 | E25: =SUM(E26:E31) -> 0 | F25: =SUM(F26:F31) -> 0 | G25: =SUM(G26:G31) -> 0 | H25: =SUM(H26:H31) -> 0 | I25: =SUM(I26:I31) -> 0 | J25: =SUM(J26:J31) -> 0 | K25: =SUM(K26:K31) -> 0 | ... W25: =SUM(W26:W31) -> 0
A26: Глава 21 | B26: ст.140 | C26: 23
A27: Глава 21 | B27: ст.141 | C27: 24
A28: Глава 21 | B28: ст.142 | C28: 25
A29: Глава 21 | B29: ст.143 | C29: 26
A30: Глава 21 | B30: ст.144 | C30: 27
A31: Глава 21 | B31: ст.145 | C31: 28
A32: Глава 22 | C32: 29 | D32: =SUM(D33:D41) -> 0 | E32: =SUM(E33:E41) -> 0 | F32: =SUM(F33:F41) -> 0 | G32: =SUM(G33:G41) -> 0 | H32: =SUM(H33:H41) -> 1 | I32: =SUM(I33:I41) -> 0 | J32: =SUM(J33:J41) -> 0 | K32: =SUM(K33:K41) -> 0 | ... W32: =SUM(W33:W41) -> 0
A33: Глава 22 | B33: ст.146 | C33: 30
A34: Глава 22 | B34: ст.147 | C34: 31
A35: Глава 22 | B35: ст.148 | C35: 32
A36: Глава 22 | B36: ст.149 | C36: 33
A37: Глава 22 | B37: ст.150 | C37: 34
A38: Глава 22 | B38: ст.151 | C38: 35
A39: Глава 22 | B39: ст.152 | C39: 36 | H39: 1
B40: ст.152-1 | C40: 37
...

Sheet Р.2
A1: Р. | B1: Наим.строки | C1: № | D1: Прокуратура | E1: МВД | F1: ГКНБ | G1: ГСИН | H1: Проверка | I1: Пр. ПРОК | J1: Пр. МВД | K1: Пр. ГКНБ | L1: Пр. ГСИН | M1: Комментарии
A2: р. 2. | D2: 1 | E2: 2 | F2: 3 | G2: 4 | H2: 5 | I2: 6 | J2: 7 | K2: 8 | L2: 9
A3: т. 2.1. | B3: Работа следственного аппарата | C3: 0 | D3: 1 | E3: 2 | F3: 3 | G3: 4 | H3: 5 | I3: 6 | J3: 7 | K3: 8 | L3: 9 | M3: 10
A4: т. 2.1. | B4: Остаток неоконченных уг.дел на начало отчетного периода | C4: 1 | E4: 66 | H4: =CONCATENATE(Р2[[#This Row],[Пр. ПРОК]]," ",Р2[[#This Row],[Пр. МВД]]," ",Р2[[#This Row],[Пр. ГКНБ]]," ",Р2[[#This Row],[Пр. ГСИН]]) | I4: =IF((D4+D5)=(D17+D47+D51+D56+D62),"",CONCATENATE("Прок: (",$C4,"+",$C5,")=(",$C17,"+",$C47,"+",$C51,"+",$C56,"+",$C62,")")) | J4: =IF((E4+E5)=(E17+E47+E51+E56+E62),"",CONCATENATE(Р2[[#Headers],[МВД]],": (",$C4,"+",$C5,")=(",$C17,"+",$C47,"+",$C51,"+",$C56,"+",$C62,")")) | K4: =IF((F4+F5)=(F17+F47+F51+F56+F62),"",CONCATENATE(Р2[[#Headers],[ГКНБ]],": (",$C4,"+",$C5,")=(",$C17,"+",$C47,"+",$C51,"+",$C56,"+",$C62,")")) | L4: =IF((G4+G5)=(G17+G47+G51+G56+G62),"",CONCATENATE(Р2[[#Headers],[ГСИН]],": (",$C4,"+",$C5,")=(",$C17,"+",$C47,"+",$C51,"+",$C56,"+",$C62,")"))
A5: т. 2.1. | B5: Принято к производству в отчетном периоде | C5: 2 | D5: =SUM(D6,D10,D11,D12,D14,D15,D16,) -> 0 | E5: =SUM(E6,E10,E11,E12,E14,E15,E16,) -> 5892 | F5: =SUM(F6,F10,F11,F12,F14,F15,F16,) -> 0 | G5: =SUM(G6,G10,G11,G12,G14,G15,G16,) -> 0 | H5: =CONCATENATE(Р2[[#This Row],[Пр. ПРОК]]," ",Р2[[#This Row],[Пр. МВД]]," ",Р2[[#This Row],[Пр. ГКНБ]]," ",Р2[[#This Row],[Пр. ГСИН]])
A6: т. 2.1. | B6: Зарегистрировано дел в ЕРП (ВУД) | C6: 3 | E6: 2866 | H6: =CONCATENATE(Р2[[#This Row],[Пр. ПРОК]]," ",Р2[[#This Row],[Пр. МВД]]," ",Р2[[#This Row],[Пр. ГКНБ]]," ",Р2[[#This Row],[Пр. ГСИН]]) -> МВД: 3=288+299+300 | I6: =IF(Р2[[#This Row],[Прокуратура]]=D291+D302+D303,"",CONCATENATE("Прок: ",Р2[[#This Row],[№]],"=",$C$291,"+",$C$302,"+",$C$303)) | J6: =IF(Р2[[#This Row],[МВД]]=E291+E302+E303,"",CONCATENATE("МВД: ",Р2[[#This Row],[№]],"=",$C$291,"+",$C$302,"+",$C$303)) -> МВД: 3=288+299+300 | K6: =IF(Р2[[#This Row],[ГКНБ]]=F291+F302+F303,"",CONCATENATE("ГКНБ: ",Р2[[#This Row],[№]],"=",$C$291,"+",$C$302,"+",$C$303)) | L6: =IF(Р2[[#This Row],[ГСИН]]=G291+G302+G303,"",CONCATENATE("ГСИН: ",Р2[[#This Row],[№]],"=",$C$291,"+",$C$302,"+",$C$303))
A7: т. 2.1. | B7: из них зарегистрировано прокурором из числа отмененых с ВУД | C7: 4 | E7: 2 | H7: =CONCATENATE(Р2[[#This Row],[Пр. ПРОК]]," ",Р2[[#This Row],[Пр. МВД]]," ",Р2[[#This Row],[Пр. ГКНБ]]," ",Р2[[#This Row],[Пр. ГСИН]]) | I7: =IF(D303=Р2[[#This Row],[Прокуратура]],"",CONCATENATE("Прок: ",Р2[[#This Row],[№]],"="&$C$303)) | J7: =IF(E303=Р2[[#This Row],[МВД]],"",CONCATENATE(Р2[[#Headers],[МВД]],": ",Р2[[#This Row],[№]],"="&$C$303)) | K7: =IF(F303=Р2[[#This Row],[ГКНБ]],"",CONCATENATE(Р2[[#Headers],[ГКНБ]],": ",Р2[[#This Row],[№]],"="&$C$303)) | L7: =IF(G303=Р2[[#This Row],[ГСИН]],"",CONCATENATE(Р2[[#Headers],[ГСИН]],": ",Р2[[#This Row],[№]],"="&$C$303))
B8: из них возбуждено следователем из числа отказанных | C8: 5 | E8: 325 | H8: =CONCATENATE(Р2[[#This Row],[Пр. ПРОК]]," ",Р2[[#This Row],[Пр. МВД]]," ",Р2[[#This Row],[Пр. ГКНБ]]," ",Р2[[#This Row],[Пр. ГСИН]]) | I8: =IF(Р2[[#This Row],[Прокуратура]]=D302,"",CONCATENATE("Прок: ",Р2[[#This Row],[№]],"=",$C$302)) | J8: =IF(Р2[[#This Row],[МВД]]=E302,"",CONCATENATE(Р2[[#Headers],[МВД]],": ",Р2[[#This Row],[№]],"=",$C$302)) | K8: =IF(Р2[[#This Row],[ГКНБ]]=F302,"",CONCATENATE(Р2[[#Headers],[ГКНБ]],": ",Р2[[#This Row],[№]],"=",$C$302)) | L8: =IF(Р2[[#This Row],[ГСИН]]=G302,"",CONCATENATE(Р2[[#Headers],[ГСИН]],": ",Р2[[#This Row],[№]],"=",$C$302))
A9: т. 2.1. | B9: из них отменено постановлений о ВУД (аннулировано) | C9: 6 | E9: 1 | H9: =CONCATENATE(Р2[[#This Row],[Пр. ПРОК]]," ",Р2[[#This Row],[Пр. МВД]]," ",Р2[[#This Row],[Пр. ГКНБ]]," ",Р2[[#This Row],[Пр. ГСИН]])
A10: т. 2.1. | B10: Принято дел из других органов | C10: 7 | E10: 58 | H10: =CONCATENATE(Р2[[#This Row],[Пр. ПРОК]]," ",Р2[[#This Row],[Пр. МВД]]," ",Р2[[#This Row],[Пр. ГКНБ]]," ",Р2[[#This Row],[Пр. ГСИН]])
A11: т. 2.1. | B11: Зарегистрировано в ЕРП из числа выделенных преступлений | C11: 8 | E11: 69 | H11: =CONCATENATE(Р2[[#This Row],[Пр. ПРОК]]," ",Р2[[#This Row],[Пр. МВД]]," ",Р2[[#This Row],[Пр. ГКНБ]]," ",Р2[[#This Row],[Пр. ГСИН]])
A12: т. 2.1. | B12: Поступило для восполнения пробелов следствия | C12: 9 | E12: 9 | H12: =CONCATENATE(Р2[[#This Row],[Пр. ПРОК]]," ",Р2[[#This Row],[Пр. МВД]]," ",Р2[[#This Row],[Пр. ГКНБ]]," ",Р2[[#This Row],[Пр. ГСИН]]) | I12: =CONCATENATE(IF((Р2[[#This Row],[Прокуратура]]-D13)=(D21-D22),"",CONCATENATE("Прок: ","(",Р2[[#This Row],[№]],"-",$C$13,")=(",$C$21,"-",$C$22,")")),IF(Р2[[#This Row],[Прокуратура]]=SUM(D215,D217,D221,D222,D223),"",CONCATENATE("Прок: ","(",$C$12,")=(",$C$215,"+",$C$217,"+",$C$221,"+",$C$223,")"))) | J12: =CONCATENATE(IF((Р2[[#This Row],[МВД]]-E13)=(E21-E22),"",CONCATENATE("МВД: ","(",Р2[[#This Row],[МВД]],"-",$C$13,")=(",$C$21,"-",$C$22,")")),IF(Р2[[#This Row],[МВД]]=SUM(E215,E217,E221,E222,E223),"",CONCATENATE("МВД: ","(",$C$12,")=(",$C$215,"+",$C$217,"+",$C$221,"+",$C$223,")"))) | K12: =CONCATENATE(IF((Р2[[#This Row],[ГКНБ]]-F13)=(F21-F22),"",CONCATENATE("ГКНБ: ","(",Р2[[#This Row],[ГКНБ]],"-",$C$13,")=(",$C$21,"-",$C$22,")")),IF(Р2[[#This Row],[ГКНБ]]=SUM(F215,F217,F221,F222,F223),"",CONCATENATE("ГКНБ: ","(",$C$12,")=(",$C$215,"+",$C$217,"+",$C$221,"+",$C$223,")"))) | L12: =CONCATENATE(IF((Р2[[#This Row],[ГСИН]]-G13)=(G21-G22),"",CONCATENATE("ГСИН: ","(",Р2[[#This Row],[ГСИН]],"-",$C$13,")=(",$C$21,"-",$C$22,")")),IF(Р2[[#This Row],[ГСИН]]=SUM(G215,G217,G221,G222,G223),"",CONCATENATE("ГСИН: ","(",$C$12,")=(",$C$215,"+",$C$217,"+",$C$221,"+",$C$223,")")))
A13: т. 2.1. | B13: из них возвращено судом | C13: 10 | E13: 6 | H13: =CONCATENATE(Р2[[#This Row],[Пр. ПРОК]]," ",Р2[[#This Row],[Пр. МВД]]," ",Р2[[#This Row],[Пр. ГКНБ]]," ",Р2[[#This Row],[Пр. ГСИН]]) | I13: =IF(D12>=Р2[[#This Row],[Прокуратура]],"",CONCATENATE("Прок: ",$C$12,">=",$C$13)) | J13: =IF(E12>=Р2[[#This Row],[МВД]],"",CONCATENATE(Р2[[#Headers],[МВД]],": ",$C$12,">=",$C$13)) | K13: =IF(F12>=Р2[[#This Row],[ГКНБ]],"",CONCATENATE(Р2[[#Headers],[ГКНБ]],": ",$C$12,">=",$C$13)) | L13: =IF(G12>=Р2[[#This Row],[ГСИН]],"",CONCATENATE(Р2[[#Headers],[ГСИН]],": ",$C$12,">=",$C$13))
A14: т. 2.1. | B14: Возобновлено производством из числа приостановленных дел | C14: 11 | E14: 2782 | H14: =CONCATENATE(Р2[[#This Row],[Пр. ПРОК]]," ",Р2[[#This Row],[Пр. МВД]]," ",Р2[[#This Row],[Пр. ГКНБ]]," ",Р2[[#This Row],[Пр. ГСИН]]) | I14: =IF((D127+D148)=Р2[[#This Row],[Прокуратура]],"",CONCATENATE("Прок: ",$C$14,"=(",$C$127,"+",$C$148,")")) | J14: =IF((E127+E148)=Р2[[#This Row],[МВД]],"",CONCATENATE(Р2[[#Headers],[МВД]],": ",$C$14,"=(",$C$127,"+",$C$148,")")) | K14: =IF((F127+F148)=Р2[[#This Row],[ГКНБ]],"",CONCATENATE(Р2[[#Headers],[ГКНБ]],": ",$C$14,"=(",$C$127,"+",$C$148,")")) | L14: =IF((G127+G148)=Р2[[#This Row],[ГСИН]],"",CONCATENATE(Р2[[#Headers],[ГСИН]],": ",$C$14,"=(",$C$127,"+",$C$148,")"))
A15: т. 2.1. | B15: Возобновлено производством из числа прекращенных дел | C15: 12 | E15: 108 | H15: =CONCATENATE(Р2[[#This Row],[Пр. ПРОК]]," ",Р2[[#This Row],[Пр. МВД]]," ",Р2[[#This Row],[Пр. ГКНБ]]," ",Р2[[#This Row],[Пр. ГСИН]]) | I15: =IF(Р2[[#This Row],[Прокуратура]]=D108,"",CONCATENATE("Прок: ",$C$15,"=",$C$108,)) | J15: =IF(Р2[[#This Row],[МВД]]=E108,"",CONCATENATE(Р2[[#Headers],[МВД]],": ",$C$15,"=",$C$108,)) | K15: =IF(Р2[[#This Row],[ГКНБ]]=F108,"",CONCATENATE(Р2[[#Headers],[ГКНБ]],": ",$C$15,"=",$C$108,)) | L15: =IF(Р2[[#This Row],[ГСИН]]=G108,"",CONCATENATE(Р2[[#Headers],[ГСИН]],": ",$C$15,"=",$C$108,))
A16: т. 2.1. | B16: Принято в произв. дел из числа оправд-х судом вступ. в закон.силу и направ.для доп.рассл. (в делах), а также из числа дел, возобн-х по новым или вновь откр.обст. | C16: 13 | H16: =CONCATENATE(Р2[[#This Row],[Пр. ПРОК]]," ",Р2[[#This Row],[Пр. МВД]]," ",Р2[[#This Row],[Пр. ГКНБ]]," ",Р2[[#This Row],[Пр. ГСИН]]) | I16: =IF(Р2[[#This Row],[Прокуратура]]=SUM(D224:D229),"",CONCATENATE("Прок: ",$C$16,"=(",$C$224,"+",$C$225,"+",$C$226,"+",$C$227,"+",$C$228,"+",$C$229,")")) | J16: =IF(Р2[[#This Row],[МВД]]=SUM(E224:E229),"",CONCATENATE(Р2[[#Headers],[МВД]],": ",$C$16,"=(",$C$224,"+",$C$225,"+",$C$226,"+",$C$227,"+",$C$228,"+",$C$229,")")) | K16: =IF(Р2[[#This Row],[ГКНБ]]=SUM(F224:F229),"",CONCATENATE(Р2[[#Headers],[ГКНБ]],": ",$C$16,"=(",$C$224,"+",$C$225,"+",$C$226,"+",$C$227,"+",$C$228,"+",$C$229,")")) | L16: =IF(Р2[[#This Row],[ГСИН]]=SUM(G224:G229),"",CONCATENATE(Р2[[#Headers],[ГСИН]],": ",$C$16,"=(",$C$224,"+",$C$225,"+",$C$226,"+",$C$227,"+",$C$228,"+",$C$229,")"))
A17: т. 2.1. | B17: Всего окончено в отчетном периоде (с повторно оконченными) | C17: 14 | E17: 3924 | H17: =CONCATENATE(Р2[[#This Row],[Пр. ПРОК]]," ",Р2[[#This Row],[Пр. МВД]]," ",Р2[[#This Row],[Пр. ГКНБ]]," ",Р2[[#This Row],[Пр. ГСИН]]) | I17: =CONCATENATE(IF(Р2[[#This Row],[Прокуратура]]=(D21+D25+D28),"",CONCATENATE("Прок: ",$C$17,"=(",$C$21,"+",$C$25,"+",$C$28,")"))," ",IF(Р2[[#This Row],[Прокуратура]]=('Отчет 1-Е Р.1'!E354+'Отчет 1-Е Р.1'!G354+'Отчет 1-Е Р.1'!E357+'Отчет 1-Е Р.1'!G357+Р.2!D29+Р.2!D115+Р.2!D215+D224),"",CONCATENATE("Прок: ",$C$17,"=(Р1:",'Отчет 1-Е Р.1'!$C$354,"(в суд)+Р1:",'Отчет 1-Е Р.1'!$C$354,"(прекращ.)+Р1:",'Отчет 1-Е Р.1'!$C$357,"(в суд)+Р1:",'Отчет 1-Е Р.1'!$C$357,"(прекращ)+",Р.2!$C$29,"+",Р.2!$C$115,"+",Р.2!$C$215,"+",Р.2!$C$224,")"))) | J17: =CONCATENATE(IF(Р2[[#This Row],[МВД]]=(E21+E25+E28),"",CONCATENATE(Р2[[#Headers],[МВД]],": ",$C$17,"=(",$C$21,"+",$C$25,"+",$C$28,")"))," ",IF(Р2[[#This Row],[МВД]]=('Отчет 1-Е Р.1'!I354+'Отчет 1-Е Р.1'!K354+'Отчет 1-Е Р.1'!I357+'Отчет 1-Е Р.1'!K357+Р.2!E29+Р.2!E115+Р.2!E215+E224),"",CONCATENATE(Р2[[#Headers],[МВД]],": ",$C$17,"=(Р1:",'Отчет 1-Е Р.1'!$C$354,"(в суд)+Р1:",'Отчет 1-Е Р.1'!$C$354,"(прекращ.)+Р1:",'Отчет 1-Е Р.1'!$C$357,"(в суд)+Р1:",'Отчет 1-Е Р.1'!$C$357,"(прекращ)+",Р.2!$C$29,"+",Р.2!$C$115,"+",Р.2!$C$215,"+",Р.2!$C$224,")"))) | K17: =CONCATENATE(IF(Р2[[#This Row],[ГКНБ]]=(F21+F25+F28),"",CONCATENATE(Р2[[#Headers],[ГКНБ]],": ",$C$17,"=(",$C$21,"+",$C$25,"+",$C$28,")"))," ",IF(Р2[[#This Row],[ГКНБ]]=('Отчет 1-Е Р.1'!M354+'Отчет 1-Е Р.1'!O354+'Отчет 1-Е Р.1'!M357+'Отчет 1-Е Р.1'!O357+Р.2!F29+Р.2!F115+Р.2!F215+F224),"",CONCATENATE(Р2[[#Headers],[ГКНБ]],": ",$C$17,"=(Р1:",'Отчет 1-Е Р.1'!$C$354,"(в суд)+Р1:",'Отчет 1-Е Р.1'!$C$354,"(прекращ.)+Р1:",'Отчет 1-Е Р.1'!$C$357,"(в суд)+Р1:",'Отчет 1-Е Р.1'!$C$357,"(прекращ)+",Р.2!$C$29,"+",Р.2!$C$115,"+",Р.2!$C$215,"+",Р.2!$C$224,")"))) | L17: =CONCATENATE(IF(Р2[[#This Row],[ГСИН]]=(G21+G25+G28),"",CONCATENATE(Р2[[#Headers],[ГСИН]],": ",$C$17,"=(",$C$21,"+",$C$25,"+",$C$28,")"))," ",IF(Р2[[#This Row],[ГСИН]]=('Отчет 1-Е Р.1'!Q354+'Отчет 1-Е Р.1'!S354+'Отчет 1-Е Р.1'!Q357+'Отчет 1-Е Р.1'!S357+Р.2!G29+Р.2!G115+Р.2!G215+G224),"",CONCATENATE(Р2[[#Headers],[ГСИН]],": ",$C$17,"=(Р1:",'Отчет 1-Е Р.1'!$C$354,"(в суд)+Р1:",'Отчет 1-Е Р.1'!$C$354,"(прекращ.)+Р1:",'Отчет 1-Е Р.1'!$C$357,"(в суд)+Р1:",'Отчет 1-Е Р.1'!$C$357,"(прекращ)+",Р.2!$C$29,"+",Р.2!$C$115,"+",Р.2!$C$215,"+",Р.2!$C$224,")")))
A18: т. 2.1. | B18: из них дел о преступ.совершенных женщинами | C18: 15 | E18: 186 | H18: =CONCATENATE(Р2[[#This Row],[Пр. ПРОК]]," ",Р2[[#This Row],[Пр. МВД]]," ",Р2[[#This Row],[Пр. ГКНБ]]," ",Р2[[#This Row],[Пр. ГСИН]]) | I18: =CONCATENATE(IF(Р2[[#This Row],[Прокуратура]]<=D17,"",CONCATENATE("Прок: ",$C$17,">=",$C$18))," ",IF(Р2[[#This Row],[Прокуратура]]>=(D23+D30),"",CONCATENATE("Прок: ",$C$18,">=","(",$C$23,"+",$C$30,")"))) | J18: =CONCATENATE(IF(Р2[[#This Row],[МВД]]<=E17,"",CONCATENATE(Р2[[#Headers],[МВД]],": ",$C$17,">=",$C$18))," ",IF(Р2[[#This Row],[МВД]]>=(E23+E30),"",CONCATENATE(Р2[[#Headers],[МВД]],": ",$C$18,">=","(",$C$23,"+",$C$30,")"))) | K18: =CONCATENATE(IF(Р2[[#This Row],[ГКНБ]]<=F17,"",CONCATENATE(Р2[[#Headers],[ГКНБ]],": ",$C$17,">=",$C$18))," ",IF(Р2[[#This Row],[ГКНБ]]>=(F23+F30),"",CONCATENATE(Р2[[#Headers],[ГКНБ]],": ",$C$18,">=","(",$C$23,"+",$C$30,")"))) | L18: =CONCATENATE(IF(Р2[[#This Row],[ГСИН]]<=G17,"",CONCATENATE(Р2[[#Headers],[ГСИН]],": ",$C$17,">=",$C$18))," ",IF(Р2[[#This Row],[ГСИН]]>=(G23+G30),"",CONCATENATE(Р2[[#Headers],[ГСИН]],": ",$C$18,">=","(",$C$23,"+",$C$30,")")))
A19: т. 2.1. | B19: из них дел о преступлениях, совершенных детьми или при их соучастии | C19: 16 | E19: 88 | H19: =CONCATENATE(Р2[[#This Row],[Пр. ПРОК]]," ",Р2[[#This Row],[Пр. МВД]]," ",Р2[[#This Row],[Пр. ГКНБ]]," ",Р2[[#This Row],[Пр. ГСИН]]) | I19: =CONCATENATE(IF(Р2[[#This Row],[Прокуратура]]<=D17,"",CONCATENATE("Прок: ",$C$17,">=",$C$19))," ",IF(Р2[[#This Row],[Прокуратура]]>=(D24+D31),"",CONCATENATE("Прок: ",$C$19,">=(",$C$24,"+",$C$31,")"))) | J19: =CONCATENATE(IF(Р2[[#This Row],[МВД]]<=E17,"",CONCATENATE(Р2[[#Headers],[МВД]],": ",$C$17,">=",$C$19))," ",IF(Р2[[#This Row],[МВД]]>=(E24+E31),"",CONCATENATE(Р2[[#Headers],[МВД]],": ",$C$19,">=(",$C$24,"+",$C$31,")"))) | K19: =CONCATENATE(IF(Р2[[#This Row],[ГКНБ]]<=F17,"",CONCATENATE(Р2[[#Headers],[ГКНБ]],": ",$C$17,">=",$C$19))," ",IF(Р2[[#This Row],[ГКНБ]]>=(F24+F31),"",CONCATENATE(Р2[[#Headers],[ГКНБ]],": ",$C$19,">=(",$C$24,"+",$C$31,")"))) | L19: =CONCATENATE(IF(Р2[[#This Row],[ГСИН]]<=G17,"",CONCATENATE(Р2[[#Headers],[ГСИН]],": ",$C$17,">=",$C$19))," ",IF(Р2[[#This Row],[ГСИН]]>=(G24+G31),"",CONCATENATE(Р2[[#Headers],[ГСИН]],": ",$C$19,">=(",$C$24,"+",$C$31,")")))
A20: т. 2.1. | B20: из них окончено дел в с нарушенным сроком следствия | C20: 17 | E20: 2604 | H20: =CONCATENATE(Р2[[#This Row],[Пр. ПРОК]]," ",Р2[[#This Row],[Пр. МВД]]," ",Р2[[#This Row],[Пр. ГКНБ]]," ",Р2[[#This Row],[Пр. ГСИН]])
A21: т. 2.1. | B21: Направлено дел прокурору (с повторно направленными) из числа оконченных с постановлением об окончании досудебного производства | C21: 18 | E21: 692 | H21: =CONCATENATE(Р2[[#This Row],[Пр. ПРОК]]," ",Р2[[#This Row],[Пр. МВД]]," ",Р2[[#This Row],[Пр. ГКНБ]]," ",Р2[[#This Row],[Пр. ГСИН]]) | I21: =IF(Р2[[#This Row],[Прокуратура]]>=D22,"",CONCATENATE("Прок: ",$C$21,">=",$C$22)) | J21: =IF(Р2[[#This Row],[МВД]]>=E22,"",CONCATENATE(Р2[[#Headers],[МВД]],": ",$C$21,">=",$C$22)) | K21: =IF(Р2[[#This Row],[ГКНБ]]>=F22,"",CONCATENATE(Р2[[#Headers],[ГКНБ]],": ",$C$21,">=",$C$22)) | L21: =IF(Р2[[#This Row],[ГСИН]]>=G22,"",CONCATENATE(Р2[[#Headers],[ГСИН]],": ",$C$21,">=",$C$22))
A22: т. 2.1. | B22: из них направлено в суд с утвержд. обвин.актом | C22: 19 | E22: 689 | H22: =CONCATENATE(Р2[[#This Row],[Пр. ПРОК]]," ",Р2[[#This Row],[Пр. МВД]]," ",Р2[[#This Row],[Пр. ГКНБ]]," ",Р2[[#This Row],[Пр. ГСИН]]) | I22: =IF(Р2[[#This Row],[Прокуратура]]>=(D23+D24),"",CONCATENATE("Прок: ",$C$22,">=(",$C$23,"+",$C$24,")")) | J22: =IF(Р2[[#This Row],[МВД]]>=(E23+E24),"",CONCATENATE(Р2[[#Headers],[МВД]],": ",$C$22,">=(",$C$23,"+",$C$24,")")) | K22: =IF(Р2[[#This Row],[ГКНБ]]>=(F23+F24),"",CONCATENATE(Р2[[#Headers],[ГКНБ]],": ",$C$22,">=(",$C$23,"+",$C$24,")")) | L22: =IF(Р2[[#This Row],[ГСИН]]>=(G23+G24),"",CONCATENATE(Р2[[#Headers],[ГСИН]],": ",$C$22,">=(",$C$23,"+",$C$24,")"))
A23: т. 2.1. | B23: в т.ч. соверш.женщинами | C23: 20 | E23: 100 | H23: =CONCATENATE(Р2[[#This Row],[Пр. ПРОК]]," ",Р2[[#This Row],[Пр. МВД]]," ",Р2[[#This Row],[Пр. ГКНБ]]," ",Р2[[#This Row],[Пр. ГСИН]])
A24: т. 2.1. | B24: в т.ч. соверш.детьми или при их соучастии | C24: 21 | E24: 19 | H24: =CONCATENATE(Р2[[#This Row],[Пр. ПРОК]]," ",Р2[[#This Row],[Пр. МВД]]," ",Р2[[#This Row],[Пр. ГКНБ]]," ",Р2[[#This Row],[Пр. ГСИН]])
A25: т. 2.1. | B25: по делам о применен.принуд.мер медиц.характера (включая детей) | C25: 22 | E25: 1 | H25: =CONCATENATE(Р2[[#This Row],[Пр. ПРОК]]," ",Р2[[#This Row],[Пр. МВД]]," ",Р2[[#This Row],[Пр. ГКНБ]]," ",Р2[[#This Row],[Пр. ГСИН]]) | I25: =CONCATENATE(IF(Р2[[#This Row],[Прокуратура]]=(D26+D27),"",CONCATENATE("Прок: ",$C$25,"=(",$C$26,"+",$C$27,")"))," ",IF(Р2[[#This Row],[Прокуратура]]=('Отчет 1-Е Р.1'!E357+'Отчет 1-Е Р.1'!G357),"",CONCATENATE("Прок: ",$C$25,"=(Р1:",'Отчет 1-Е Р.1'!$C$357,"(в суд)+Р1:",'Отчет 1-Е Р.1'!$C$357,"(прекращ.))"))) | J25: =CONCATENATE(IF(Р2[[#This Row],[МВД]]=(E26+E27),"",CONCATENATE(Р2[[#Headers],[МВД]],": ",$C$25,"=(",$C$26,"+",$C$27,")"))," ",IF(Р2[[#This Row],[МВД]]=('Отчет 1-Е Р.1'!I357+'Отчет 1-Е Р.1'!K357),"",CONCATENATE(Р2[[#Headers],[МВД]],": ",$C$25,"=(Р1:",'Отчет 1-Е Р.1'!$C$357,"(в суд)+Р1:",'Отчет 1-Е Р.1'!$C$357,"(прекращ.))"))) | K25: =CONCATENATE(IF(Р2[[#This Row],[ГКНБ]]=(F26+F27),"",CONCATENATE(Р2[[#Headers],[ГКНБ]],": ",$C$25,"=(",$C$26,"+",$C$27,")"))," ",IF(Р2[[#This Row],[ГКНБ]]=('Отчет 1-Е Р.1'!M357+'Отчет 1-Е Р.1'!O357),"",CONCATENATE(Р2[[#Headers],[ГКНБ]],": ",$C$25,"=(Р1:",'Отчет 1-Е Р.1'!$C$357,"(в суд)+Р1:",'Отчет 1-Е Р.1'!$C$357,"(прекращ.))"))) | L25: =CONCATENATE(IF(Р2[[#This Row],[ГСИН]]=(G26+G27),"",CONCATENATE(Р2[[#Headers],[ГСИН]],": ",$C$25,"=(",$C$26,"+",$C$27,")"))," ",IF(Р2[[#This Row],[ГСИН]]=('Отчет 1-Е Р.1'!Q357+'Отчет 1-Е Р.1'!S357),"",CONCATENATE(Р2[[#Headers],[ГСИН]],": ",$C$25,"=(Р1:",'Отчет 1-Е Р.1'!$C$357,"(в суд)+Р1:",'Отчет 1-Е Р.1'!$C$357,"(прекращ.))")))
A26: т. 2.1. | B26: из них направлено в суд | C26: 23 | E26: 1 | H26: =CONCATENATE(Р2[[#This Row],[Пр. ПРОК]]," ",Р2[[#This Row],[Пр. МВД]]," ",Р2[[#This Row],[Пр. ГКНБ]]," ",Р2[[#This Row],[Пр. ГСИН]])
A27: т. 2.1. | B27: из них окончено повторно | C27: 24 | H27: =CONCATENATE(Р2[[#This Row],[Пр. ПРОК]]," ",Р2[[#This Row],[Пр. МВД]]," ",Р2[[#This Row],[Пр. ГКНБ]]," ",Р2[[#This Row],[Пр. ГСИН]])
A28: т. 2.1. | B28: Прекращено дел из числа оконченных производством | C28: 25 | E28: 3231 | H28: =CONCATENATE(Р2[[#This Row],[Пр. ПРОК]]," ",Р2[[#This Row],[Пр. МВД]]," ",Р2[[#This Row],[Пр. ГКНБ]]," ",Р2[[#This Row],[Пр. ГСИН]]) | I28: =CONCATENATE(IF((Р2[[#This Row],[Прокуратура]]-D124)=('Отчет 1-Е Р.1'!G354+Р.2!D29),"",CONCATENATE("Прок: ",": (",$C$28,"-",$C124,")=(Р1:",'Отчет 1-Е Р.1'!$C$354,"(Прекращ.)+",Р.2!$C$29,")"))," ",IF(Р2[[#This Row],[Прокуратура]]>=(D31+D30),"",CONCATENATE("Прок: ",$C$28,">=(",$C$30,"+",$C$31,")"))) | J28: =CONCATENATE(IF((Р2[[#This Row],[МВД]]-E124)=('Отчет 1-Е Р.1'!K354+Р.2!E29),"",CONCATENATE(Р2[[#Headers],[МВД]],": (",$C$28,"-",$C124,")=(Р1:",'Отчет 1-Е Р.1'!$C$354,"(Прекращ.)+",Р.2!$C$29,")"))," ",IF(Р2[[#This Row],[МВД]]>=(E31+E30),"",CONCATENATE(Р2[[#Headers],[МВД]],": ",$C$28,">=(",$C$30,"+",$C$31,")"))) | K28: =CONCATENATE(IF((Р2[[#This Row],[ГКНБ]]-F124)=('Отчет 1-Е Р.1'!O354+Р.2!F29),"",CONCATENATE(Р2[[#Headers],[ГКНБ]],": (",$C$28,"-",$C124,")=(Р1:",'Отчет 1-Е Р.1'!$C$354,"(Прекращ.)+",Р.2!$C$29,")"))," ",IF(Р2[[#This Row],[ГКНБ]]>=(F31+F30),"",CONCATENATE(Р2[[#Headers],[ГКНБ]],": ",$C$28,">=(",$C$30,"+",$C$31,")"))) | L28: =CONCATENATE(IF((Р2[[#This Row],[ГСИН]]-G124)=('Отчет 1-Е Р.1'!S354+Р.2!G29),"",CONCATENATE(Р2[[#Headers],[ГСИН]],": (",$C$28,"-",$C124,")=(Р1:",'Отчет 1-Е Р.1'!$C$354,"(Прекращ.)+",Р.2!$C$29,")"))," ",IF(Р2[[#This Row],[ГСИН]]>=(G31+G30),"",CONCATENATE(Р2[[#Headers],[ГСИН]],": ",$C$28,">=(",$C$30,"+",$C$31,")")))
A29: т. 2.1. | B29: из них прекращено повторно, без учета прекращенных после доследования | C29: 26 | E29: 85 | H29: =CONCATENATE(Р2[[#This Row],[Пр. ПРОК]]," ",Р2[[#This Row],[Пр. МВД]]," ",Р2[[#This Row],[Пр. ГКНБ]]," ",Р2[[#This Row],[Пр. ГСИН]]) | I29: =IF(Р2[[#This Row],[Прокуратура]]<=D28,"",CONCATENATE("Прок: ",$C$28,">=",$C$29)) | J29: =IF(Р2[[#This Row],[МВД]]<=E28,"",CONCATENATE(Р2[[#Headers],[МВД]],": ",$C$28,">=",$C$29)) | K29: =IF(Р2[[#This Row],[ГКНБ]]<=F28,"",CONCATENATE(Р2[[#Headers],[ГКНБ]],": ",$C$28,">=",$C$29)) | L29: =IF(Р2[[#This Row],[ГСИН]]<=G28,"",CONCATENATE(Р2[[#Headers],[ГСИН]],": ",$C$28,">=",$C$29))
A30: т. 2.1. | B30: из них совершенных женщинами | C30: 27 | E30: 86 | H30: =CONCATENATE(Р2[[#This Row],[Пр. ПРОК]]," ",Р2[[#This Row],[Пр. МВД]]," ",Р2[[#This Row],[Пр. ГКНБ]]," ",Р2[[#This Row],[Пр. ГСИН]])
A31: т. 2.1. | B31: из них совершенных детьми или при их соучастии | C31: 28 | E31: 69 | H31: =CONCATENATE(Р2[[#This Row],[Пр. ПРОК]]," ",Р2[[#This Row],[Пр. МВД]]," ",Р2[[#This Row],[Пр. ГКНБ]]," ",Р2[[#This Row],[Пр. ГСИН]])
A32: т. 2.1. | B32: Число лиц, о которых производ.прекращ. по реабилит.основаниям | C32: 29 | E32: 1 | H32: =CONCATENATE(Р2[[#This Row],[Пр. ПРОК]]," ",Р2[[#This Row],[Пр. МВД]]," ",Р2[[#This Row],[Пр. ГКНБ]]," ",Р2[[#This Row],[Пр. ГСИН]]) | I32: =IF(Р2[[#This Row],[Прокуратура]]>=(D34+D35),"",CONCATENATE("Прок: ",$C$32,">=(",$C$34,"+",$C$35,")")) | J32: =IF(Р2[[#This Row],[МВД]]>=(E34+E35),"",CONCATENATE(Р2[[#Headers],[МВД]],": ",$C$32,">=(",$C$34,"+",$C$35,")")) | K32: =IF(Р2[[#This Row],[ГКНБ]]>=(F34+F35),"",CONCATENATE(Р2[[#Headers],[ГКНБ]],": ",$C$32,">=(",$C$34,"+",$C$35,")")) | L32: =IF(Р2[[#This Row],[ГСИН]]>=(G34+G35),"",CONCATENATE(Р2[[#Headers],[ГСИН]],": ",$C$32,">=(",$C$34,"+",$C$35,")"))
B33: из них предъявлено обвинений (уведомлено о подозрении) другим органом | C33: 30 | H33: =CONCATENATE(Р2[[#This Row],[Пр. ПРОК]]," ",Р2[[#This Row],[Пр. МВД]]," ",Р2[[#This Row],[Пр. ГКНБ]]," ",Р2[[#This Row],[Пр. ГСИН]])
A34: т. 2.1. | B34: из них женщин | C34: 31 | H34: =CONCATENATE(Р2[[#This Row],[Пр. ПРОК]]," ",Р2[[#This Row],[Пр. МВД]]," ",Р2[[#This Row],[Пр. ГКНБ]]," ",Р2[[#This Row],[Пр. ГСИН]])
A35: т. 2.1. | B35: из них детей | C35: 32 | H35: =CONCATENATE(Р2[[#This Row],[Пр. ПРОК]]," ",Р2[[#This Row],[Пр. МВД]]," ",Р2[[#This Row],[Пр. ГКНБ]]," ",Р2[[#This Row],[Пр. ГСИН]])
A36: т. 2.1. | B36: Из учтенных содержалось под стражей | C36: 33 | H36: =CONCATENATE(Р2[[#This Row],[Пр. ПРОК]]," ",Р2[[#This Row],[Пр. МВД]]," ",Р2[[#This Row],[Пр. ГКНБ]]," ",Р2[[#This Row],[Пр. ГСИН]]) | I36: =IF(Р2[[#This Row],[Прокуратура]]>=(D38+D39),"",CONCATENATE("Прок: ",$C$36,">=(",$C$38,"+",$C$39,")")) | J36: =IF(Р2[[#This Row],[МВД]]>=(E38+E39),"",CONCATENATE(Р2[[#Headers],[МВД]],": ",$C$36,">=(",$C$38,"+",$C$39,")")) | K36: =IF(Р2[[#This Row],[ГКНБ]]>=(F38+F39),"",CONCATENATE(Р2[[#Headers],[ГКНБ]],": ",$C$36,">=(",$C$38,"+",$C$39,")")) | L36: =IF(Р2[[#This Row],[ГСИН]]>=(G38+G39),"",CONCATENATE(Р2[[#Headers],[ГСИН]],": ",$C$36,">=(",$C$38,"+",$C$39,")"))
B37: из них кол. задержанных по ст. 96 УПК | C37: 34 | H37: =CONCATENATE(Р2[[#This Row],[Пр. ПРОК]]," ",Р2[[#This Row],[Пр. МВД]]," ",Р2[[#This Row],[Пр. ГКНБ]]," ",Р2[[#This Row],[Пр. ГСИН]])
A38: т. 2.1. | B38: из них женщин | C38: 35 | H38: =CONCATENATE(Р2[[#This Row],[Пр. ПРОК]]," ",Р2[[#This Row],[Пр. МВД]]," ",Р2[[#This Row],[Пр. ГКНБ]]," ",Р2[[#This Row],[Пр. ГСИН]])
A39: т. 2.1. | B39: из них детей | C39: 36 | H39: =CONCATENATE(Р2[[#This Row],[Пр. ПРОК]]," ",Р2[[#This Row],[Пр. МВД]]," ",Р2[[#This Row],[Пр. ГКНБ]]," ",Р2[[#This Row],[Пр. ГСИН]])
A40: т. 2.1. | B40: Отменено прокурорами (судами) постан. о прекращ. уг. преслед. в делах | C40: 37 | H40: =CONCATENATE(Р2[[#This Row],[Пр. ПРОК]]," ",Р2[[#This Row],[Пр. МВД]]," ",Р2[[#This Row],[Пр. ГКНБ]]," ",Р2[[#This Row],[Пр. ГСИН]])
...

Sheet БАЗА
A1: орган | B1: шифр
A2: ГЕНЕРАЛЬНАЯ ПРОКУРАТУРА КЫРГЫЗСКОЙ РЕСПУБЛИКИ | B2: 150
A3: ПРОКУРАТУРА Г. БИШКЕК | B3: 151
A4: ПРОКУРАТУРА Г. ОШ | B4: 141
A5: ПРОКУРАТУРА ЧУЙСКОЙ ОБЛАСТИ | B5: 173
A6: ПРОКУРАТУРА ОШСКОЙ ОБЛАСТИ | B6: 152
A7: ПРОКУРАТУРА ИССЫК-КУЛЬСКОЙ ОБЛАСТИ | B7: 153
A8: ПРОКУРАТУРА НАРЫНСКОЙ ОБЛАСТИ | B8: 154
A9: ПРОКУРАТУРА ДЖАЛАЛ-АБАДСКОЙ ОБЛАСТИ | B9: 172
A10: ПРОКУРАТУРА ТАЛАССКОЙ ОБЛАСТИ | B10: 170
A11: ПРОКУРАТУРА БАТКЕНСКОЙ ОБЛАСТИ | B11: 186
A12: ПРОКУРАТУРА ПЕРВОМАЙСКОГО РАЙОНА | B12: 102
A13: ПРОКУРАТУРА ЛЕНИНСКОГО РАЙОНА | B13: 101
... A74: ВОЕННАЯ ПРОКУРАТУРА ЖАЛАЛ-АБАДСКОГО ГАРНИЗОНА | B74: 805
A75: ГСУ МВД | B75: 050
A76: ГСУ МВД (ПО ЮЖНОМУ РЕГИОНУ) | B76: '095
A77: ГУВД Г.БИШКЕК | B77: '051
A78: УВД Г.ОШ | B78: '041
A79: УВД БАТКЕНСКОЙ ОБЛАСТИ | B79: '086
A80: УВД ДЖАЛАЛ-АБАДСКОЙ ОБЛАСТИ | B80: '072
A81: УВД НАРЫНСКОЙ ОБЛАСТИ | B81: '054
A82: УВД ОШСКОЙ ОБЛАСТИ | B82: '052
A83: УВД ТАЛАССКОЙ ОБЛАСТИ | B83: '070
A84: ГУВД ЧУЙСКОЙ ОБЛАСТИ | B84: '073
A85: УВД ИССЫК-КУЛЬСКОЙ ОБЛАСТИ | B85: '053
A86: УВДТ (НА ЖДТ) | B86: '081
... A147: АК-БУУРА (Г.ОШ) | B147: '092
A148: ГКНБ КЫРГЫЗСКОЙ РЕСПУБЛИКИ | B148: 820
A149: ГУ ГКНБ ПО Г. БИШКЕК | B149: 828
A150: УГКНБ КР ПО Г.ОШ И ОШСКОЙ ОБЛАСТИ | B150: 821
A151: УГКНБ КР ПО ЖАЛАЛ-АБАДСКОЙ ОБЛАСТИ | B151: 822
A152: УГКНБ КР ПО БАТКЕНСКОЙ ОБЛАСТИ | B152: 823
A153: УГКНБ КР ПО ИССЫК-КУЛЬСКОЙ ОБЛАСТИ | B153: 824
A154: УГКНБ КР ПО ЧУЙСКОЙ ОБЛАСТИ | B154: 825
A155: УГКНБ КР ПО НАРЫНСКОЙ ОБЛАСТИ | B155: 826
A156: УГКНБ КР ПО ТАЛАССКОЙ ОБЛАСТИ | B156: 827
A157: ГСИН ПРИ ПКР | B157: 860
A158: ГТС ПРИ ПКР | B158: 850
A159: РЕЗЕРВ
A160: ГСБЭП ПРИ ПКР | B160: 300
...
